<?xml version="1.0" encoding="UTF-8"?>
<robot name="aironbot">
  
  <material name="blue">
    <color rgba="0 0 0.8 1"/>
  </material>

  <material name="white">
    <color rgba="0.9 0.9 0.9 1"/>
  </material>
   
   <link name="base_link">
      <visual>
         <geometry>
            <mesh filename="package://aironbot_description/meshes/manipulator_base_link.stl" />
         </geometry>
         <material name="blue"/>
      </visual>
   </link>
   
   <link name="link_1">
      <visual>
         <geometry>
            <mesh filename="package://aironbot_description/meshes/manipulator_link.stl" />
         </geometry>
         <material name="white"/>
      </visual>
   </link>
   
   <joint name="link_1_to_base" type="continuous">
      <parent link="base_link" />
      <child link="link_1" />
      <origin xyz="0 0 0.14" />
      <axis xyz="0 1 0" />
   </joint>

</robot>
